Workbook

Sheet chemische Grundlagen
A1: molare Massen
B2: kg/kmol
A3: molare Masse Fe | B3: 56
A4: molare Masse Fe2O3 | B4: =2*56+3*16 -> 160
A5: molare Masse Si | B5: 28
A6: molare Masse SiO2 | B6: 60
A7: molare Masse Ca | B7: 40
A8: molare Masse CaO | B8: 56
A9: molare Masse CaCO3 | B9: =B8+B15 -> 100
A10: molare Masse O | B10: 16
A11: molare Masse O2 | B11: 32
A12: molare Masse N2 | B12: 28
A13: molare Masse C | B13: 12
A14: molare Masse CO | B14: 28
A15: molare Masse CO2 | B15: 44

Sheet Massenbilanz
A1: Hochofen-Massenbilanz
H2: A) Berechnungsmatrix (Umrechnung der Zusammensetzung auf Massenkonzentration der Elemente) in %
A3: Einsatzstoffe | I3: Erz (1) | J3: Zuschläge (2) | K3: Koks (3) | L3: Heißwind (4) | M3: Gichtgas (5) | N3: Schlacke (6) | O3: Roheisen (7)
A4: Eisenerz | B4: [%] | C4: Menge [kg/tHM] | D4: Menge [kmol/tHM] | H4: Fe | I4: =B5*112/160 -> 66.08 | O4: 95.7
A5: Fe2O3 | B5: 94.4 | C5: =$B$9*B5/100 -> 1367.1429 | D5: =C5/160 -> 8.5446429 | H5: Si | I5: =2.5*28/60 -> 1.1666667 | K5: =B18*28/60 -> 6.0666667 | N5: =B40*28/60 -> 23.333333 | O5: 0.3
A6: SiO2 | B6: 2.5 | C6: =$B$9*B6/100 -> 36.206114 | D6: =C6/60 -> 0.60343523 | H6: Ca | I6: =3.1*40/56 -> 2.2142857 | J6: =100*40/100 -> 40 | N6: =B41*40/56 -> 35.714286
A7: CaO | B7: 3.1 | C7: =$B$9*B7/100 -> 44.895581 | D7: =C7/56 -> 0.80170681 | H7: C | J7: 12 | K7: 87 | M7: =M18/M21*100 -> 16.959729 | O7: 4
H8: O | I8: =100-I4-I5-I6 -> 30.539048 | J8: =100*48/100 -> 48 | K8: =100-K5-K7 -> 6.9333333 | L8: =100-L9 -> 23.300971 | M8: =M19/M21*100 -> 33.523817 | N8: =100-N6-N5 -> 40.952381
A9: Menge [kg/tHM] | B9: =I22 -> 1448.2446 | H9: N | L9: =(B23*28)/(B23*28+B24*32)*100 -> 76.699029 | M9: =100-M7-M8 -> 49.516454
H10: Summe | I10: =SUM(I4:I9) -> 100 | J10: =SUM(J4:J9) -> 100 | K10: =SUM(K4:K9) -> 100 | L10: =SUM(L4:L9) -> 100 | M10: =SUM(M4:M9) -> 100 | N10: =SUM(N4:N9) -> 100 | O10: =SUM(O4:O9) -> 100
A11: Zuschläge | B11: [%] | C11: Menge [kg/tHM] | D11: Menge [kmol/tHM]
A12: CaCO3 | B12: 100
H13: B) Massenbilanz der Elemente in kg bzw. kg/tHM
A14: Menge [kg/tHM] | B14: =J21 -> 89.08 | I14: Erz (1) | J14: Zuschläge (2) | K14: Koks (3) | L14: Heißwind (4) | M14: Gichtgas (5) | N14: Schlacke (6) | O14: Roheisen (7) | P14: Gesamt
H15: Fe | I15: =$I$21*I4/100 -> 957 | O15: 957 | Q15: a) Fe-bilanz | R15: =O15/(I4/100) -> 1448.2446 | S15: kg (Eisenerz)
A16: Koks | B16: [%] | C16: Menge [kg/tHM] | D16: Menge [kmol/tHM] | H16: Si | I16: =$I$21*I5/100 -> 16.896186 | K16: =$K$21*K5/100 -> 30.333333 | N16: =$N$21*N5/100 -> 44.230667 | O16: 3 | Q16: b) Si-Bilanz | R16: =(I5*I21+K5*B20-O5*O21)/N5 -> 189.55508 | S16: kg (Schlacke)
A17: C | B17: 87 | H17: Ca | I17: =$I$21*I6/100 -> 32.068272 | J17: =$J$21*J6/100 -> 35.632 | N17: =$N$21*N6/100 -> 67.7 | Q17: c) Ca-Bilanz | R17: =(N17-I17)/(J6/100) -> 89.079319 | S17: kg (Zuschläge)
A18: SiO2 | B18: 13 | H18: C | J18: =$J$21*J7/100 -> 10.6896 | K18: =$K$21*K7/100 -> 435 | M18: =R18 -> 405.6896 | O18: 40 | Q18: d) C-Bilanz | R18: =J18+K18-O18 -> 405.6896 | S18: kg (im Gichtgas)
H19: O | I19: =$I$21*I8/100 -> 442.28009 | J19: =$J$21*J8/100 -> 42.7584 | K19: =$K$21*K8/100 -> 34.666667 | L19: =D24*32 -> 359.83936 | M19: =R19 -> 801.91518 | N19: =$N$21*N8/100 -> 77.629333 | Q19: e) Berechnen O | R19: =I19+J19+K19+L19-N19 -> 801.91518 | S19: kg O im Gichtgas
A20: Menge [kg/tHM] | B20: 500 | H20: N | L20: =D23*28 -> 1184.4712 | M20: =L20 -> 1184.4712
H21: Summe | I21: =R15 -> 1448.2446 | J21: 89.08 | K21: 500 | L21: =SUM(L15:L20) -> 1544.3106 | M21: =SUM(M15:M20) -> 2392.076 | N21: 189.56 | O21: =SUM(O15:O20) -> 1000
A22: Heißwind | B22: [%] | C22: Menge [Nm³/tHM] | D22: Menge [kmol/tHM] | I22: =SUM(I15:I20) -> 1448.2446 | J22: =SUM(J15:J20) -> 89.08 | K22: =SUM(K15:K20) -> 500 | N22: =SUM(N15:N20) -> 189.56
A23: N2 | B23: 79 | C23: =B23/100*B26 -> 948 | D23: =C23/22.41 -> 42.302544
A24: O2 | B24: 21 | C24: =B24/100*B26 -> 252 | D24: =C24/22.41 -> 11.24498
A26: Menge [Nm³/tHM] | B26: 1200
A30: Produkte
F31: C) Bilanzierung der Gichtgas
A32: Gichtgas | B32: [mol-%] | C32: Menge [Nm³/tHM] | D32: Menge [kmol/tHM] | E32: Menge [kg/tHM] | G32: Menge [kmol/tHM]
A33: N2 | B33: =D33/D37*100 -> 55.513296 | C33: =D33*22.41 -> 948 | D33: =G33 -> 42.302544 | E33: =D33*28 -> 1184.4712 | F33: N2 | G33: =M20/28 -> 42.302544
A34: CO2 | B34: =D34/D37*100 -> 21.521591 | C34: =D34*22.41 -> 367.524 | D34: 16.4 | E34: =D34*44 -> 721.6 | F34: C | G34: =M18/12 -> 33.807467
A35: CO | B35: =D35/D37*100 -> 22.965113 | C35: =D35*22.41 -> 392.175 | D35: 17.5 | E35: =D35*28 -> 490 | F35: O | G35: =M19/16 -> 50.119699 | H35: > lineares Gleichungssystem
H36: GOD | I36: =B34/(B34+B35)*100 -> 48.377581
A37: Menge [Nm³/tHM] | B37: =SUM(C33:C35) -> 1707.699 | D37: =SUM(D33:D35) -> 76.202544
A39: Schlacke | B39: [%] | C39: Menge [kg/tHM] | D39: Menge [kmol/tHM]
A40: CaO | B40: 50
A41: SiO2 | B41: 50
A43: B2 | B43: 1
A44: Menge [kg/tHM] | B44: =N21 -> 189.56
A46: Roheisen | B46: [%] | C46: Menge [kg/tHM] | D46: Menge [kmol/tHM]
A47: Fe | B47: 95.7
...

Sheet Rist-Diagram
A1: Hochofen-Ristdiagramm
A3: Erstellen der Betriebsgeraden
B4: kmol/t HM
A5: O Wind | B5: =2*Massenbilanz!D24 -> 22.48996
A6: OSi | B6: =3/28*2 -> 0.21428571
A8: Sum O extern | B8: =B5+B6 -> 22.704246 | C8: aus Heißwind und SiO2
A9: Sum O
A11: Fe | B11: =Massenbilanz!I15/'chemische Grundlagen'!B3 -> 17.089286
A12: C | B12: =(Massenbilanz!K18-Massenbilanz!O18)/'chemische Grundlagen'!B13 -> 32.916667 | C12: C nur für Reduktion | F12: 1 | G12: -2
F13: 1 | G13: 1.5
A14: O/Fe | B14: =-B8/B11 -> -1.3285661 | C14: Ordinatenabschnitt d
A15: C/Fe | B15: =B12/B11 -> 1.9261581 | C15: Steigung k
A20: Anteil indirekte/direkte Reduktion
A21: Graphical display | C21: y=k*x+d | D21: (O/Fe)=k*(O/C)+d
B22: O/C | C22: O/Fe
B23: 0 | C23: =$B$15*B23+B14 -> -1.3285661 | D23: O/Fe-Verhältnis der Inputstoffe (Einsetzen von Punkt I in Geradengleichung)
B24: 1 | C24: =$B$15*B24+B14 -> 0.59759204
B25: 2 | C25: =$B$15*B25+B14 -> 2.5237502
A27: RG | B27: =(1.5-C24)/1.5*100 -> 60.160531 | C27: indirect reduction | E27: einsetzen in Gleichung für O/C=1
B28: =100-B27 -> 39.839469 | C28: direct reduction
A30: GOD Gichtgas
B32: O/C | C32: =(1.5-B14)/B15 -> 1.4685015 | E32: einsetzen in Gleichung für O/Fe=1.5
B33: GOD (RIST) | C33: =(C32-1)*100 -> 46.850149
B34: GOD (Massen) | C34: 48.38 | E34: Differenz durch Kalzinierung von Kalk
A37: Konstruktion Wüstitecke (bei 1200°C)
J38: Glgw.-Linien | K38: x (O/C) | L38: y (O/Fe)
A39: Glgw. CO/CO2 | B39: X (CO2) | C39: 0.24 | D39: aus Baur Glaessner für Fe/FeO | K39: 1.24 | L39: 0
B40: X (CO2) | C40: 0.86 | D40: aus Baur Glaessner für FeO/Fe3O4 | K40: 1.24 | L40: 1.0491803
K41: 1.86 | L41: 1.173913
A42: Glgw. O/Fe | B42: Fe/Wü | C42: 51.2 | D42: aus Fe-O-System | F42: O/Fe | G42: =C42/(100-C42) -> 1.0491803 | K42: 1.86 | L42: 1.3364486
B43: Wü/Mag+Wu | C43: 54 | D43: aus Fe-O-System | F43: O/Fe | G43: =C43/(100-C43) -> 1.173913 | K43: 2 | L43: 1.3529412
B44: Mag+Wu/Mag | C44: 57.2 | D44: aus Fe-O-System | F44: O/Fe | G44: =C44/(100-C44) -> 1.3364486
B45: Mag/Hem+Mag | C45: 57.5 | D45: aus Fe-O-System | F45: O/Fe | G45: =C45/(100-C45) -> 1.3529412
A47: Konstruktion Wüstitecke (bei 900°C)
J48: Glgw.-Linien | K48: x (O/C) | L48: y (O/Fe)
A49: Glgw. CO/CO2 | B49: X (CO2) | C49: 0.3 | D49: aus Baur Glaessner für Fe/FeO | K49: 1.3 | L49: 0
B50: X (CO2) | C50: 0.77 | D50: aus Baur Glaessner für FeO/Fe3O4 | K50: 1.3 | L50: 1.0491803
K51: 1.77 | L51: 1.1276596
A52: Glgw. O/Fe | B52: Fe/Wü | C52: 51.2 | D52: aus Fe-O-System | F52: O/Fe | G52: =C52/(100-C52) -> 1.0491803 | K52: 1.77 | L52: 1.3364486
B53: Wü/Mag+Wu | C53: 53 | D53: aus Fe-O-System | F53: O/Fe | G53: =C53/(100-C53) -> 1.1276596 | K53: 2 | L53: 1.3419204
...

Sheet Energiebilanz
B1: Hochofen-Energiebilanz
C3: Input | G3: Output
C4: Erz | D4: Zuschläge | E4: Koks | F4: Heißwind | G4: Gichtgas | H4: Schlacke | I4: Roheisen | J4: Verluste | K4: Summe
A5: Masse [kg] | C5: 1448.24 | D5: 89.07 | E5: 500 | F5: 1544 | G5: -2392.07 | H5: -189.56 | I5: -1000
A6: Temperatur [°C] | C6: 25 | D6: 25 | E6: 25 | F6: 1200 | G6: =D56 -> 342.46838 | H6: 1500 | I6: 1500
A7: Zusammensetzung (Massenanteil in %) | B7: Fe2O3 | C7: 94.4
B8: RE | I8: 100
B9: SiO2 | C9: 2.5 | E9: 13
B10: CaO | C10: 3.1
B11: CaCO3 | D11: 100
B12: CaO-SiO2 | H12: 100
B13: C | E13: 87
B14: N2 | F14: 76.7 | G14: 49.51
B15: O2 | F15: 23.3
B16: CO
B17: CO2
A18: Enthalpie [MJ] | C18: =C5*C19 -> -8114.7339 | D18: =D19*D5 -> -1074.7774 | E18: =E19*E5 -> -986.59167 | F18: =F19*F5 -> 2031.4644 | G18: =C18+D18+E18+F18+H18+I18+J18 -> -1588.4361 | H18: =H19*H5 -> 5882.8966 | I18: =I19*I5 -> -1026.694 | J18: 1700
A19: spez. Enthalpie [MJ/kg] | C19: =C7/100*E26+C9/100*E28+C10/100*E29 -> -5.6031693 | D19: =D11/100*E30 -> -12.06666 | E19: =E9/100*E28+E13/100*E32 -> -1.9731833 | F19: =F14/100*E33+F15/100*E34 -> 1.3157153 | G19: =G18/G5 -> 0.66404249 | H19: =H12/100*E31 -> -31.034483 | I19: =I8/100*E27 -> 1.026694
B25: Angaben | C25: spez. Enthalpie [KJ/kmol] | D25: MG [kg/kmol] | E25: spez. Enthalpie [MJ/kg]
B26: Fe2O3 | C26: -825787 | D26: 160 | E26: =C26/D26*10^-3 -> -5.1611687
B27: RE | C27: 50000 | D27: 48.7 | E27: =C27/D27*10^-3 -> 1.026694
B28: SiO2 | C28: -910700 | D28: 60 | E28: =C28/D28*10^-3 -> -15.178333
B29: CaO | C29: -635090 | D29: 56 | E29: =C29/D29*10^-3 -> -11.340893
B30: CaCO3 | C30: -1206666 | D30: 100 | E30: =C30/D30*10^-3 -> -12.06666
B31: CaO-SiO2 | C31: -3600000 | D31: 116 | E31: =C31/D31*10^-3 -> -31.034483
B32: C | C32: 0 | D32: 12 | E32: =C32/D32*10^-3 -> 0
B33: N2 | C33: 37500 | D33: 28 | E33: =C33/D33*10^-3 -> 1.3392857
B34: O2 | C34: 39620 | D34: 32 | E34: =C34/D34*10^-3 -> 1.238125
C35: bei den gegebenen Temperaturen
B39: Gichtgaszusammensetzung
C40: [mol-%] | D40: [wt-%]
B41: N2 | C41: 55.59 | D41: =1184.47/SUM(Massenbilanz!E33:E35)*100 -> 49.433839
B42: CO2 | C42: 21.46 | D42: =721.6/SUM(Massenbilanz!E33:E35)*100 -> 30.115966
B43: CO | C43: 22.96 | D43: =490/SUM(Massenbilanz!E33:E35)*100 -> 20.450143
D45: MG (Gichtgas) | F45: kg/kmol | G45: 31.44
B48: Gichtgastemperatur (mit cp-Werten für 600°C)
C49: cp(J/molK) | D49: cp(MJ/kgK)
B50: N2 | C50: 30.15 | D50: =C50/28*10^-3 -> 0.0010767857
B51: CO2 | C51: 47.36 | D51: =C51/44*10^-3 -> 0.0010763636
B52: CO | C52: 30.46 | D52: =C52/28*10^-3 -> 0.0010878571
...
